Workbook

Sheet Portfolio
B2: Notional | C2: Effective Date | D2: Maturity | E2: Pay Leg | F2: Pay Leg Currency | G2: Pay Leg Frequency | H2: Pay Leg Day Count | I2: Rec Leg | J2: Rec Leg Currency | K2: Rec Leg Frequency | L2: Rec Leg Day Count | M2: Fixed Rate | N2: Float Reset Type
B3: 9836000 | C3: 44168 | D3: 46042 | E3: SOFR | F3: USD | G3: 4 | H3: ACT/360 | I3: FIXED | J3: USD | K3: 4 | L3: 30/360 | M3: 3.403 | N3: In Arrears
B4: 5356000 | C4: 44349 | D4: 49032 | E4: LIB1 | F4: USD | G4: 12 | H4: ACT/360 | I4: FIXED | J4: USD | K4: 12 | L4: 30/360 | M4: 3.886 | N4: In Advance
B5: 5056000 | C5: 45332 | D5: 48668 | E5: LIB3 | F5: USD | G5: 4 | H5: ACT/360 | I5: FIXED | J5: USD | K5: 4 | L5: 30/360 | M5: 1.055 | N5: In Advance
B6: 9686000 | C6: 45469 | D6: 50928 | E6: FED FUNDS | F6: USD | G6: 1 | H6: ACT/360 | I6: FIXED | J6: USD | K6: 1 | L6: 30/360 | M6: 4.482 | N6: In Arrears
B7: 6822000 | C7: 44478 | D7: 47691 | E7: FIXED | F7: USD | G7: 12 | H7: 30/360 | I7: SOFR | J7: USD | K7: 12 | L7: ACT/360 | M7: 1.958 | N7: In Arrears
B8: 3727000 | C8: 44372 | D8: 49542 | E8: FIXED | F8: USD | G8: 12 | H8: 30/360 | I8: LIB1 | J8: USD | K8: 12 | L8: ACT/360 | M8: 2.143 | N8: In Advance
B9: 3259000 | C9: 44147 | D9: 46122 | E9: FIXED | F9: USD | G9: 12 | H9: 30/360 | I9: SOFR | J9: USD | K9: 12 | L9: ACT/360 | M9: 4.241 | N9: In Arrears
B10: 880000 | C10: 45163 | D10: 47491 | E10: FIXED | F10: USD | G10: 12 | H10: 30/360 | I10: LIB1 | J10: USD | K10: 12 | L10: ACT/360 | M10: 2.899 | N10: In Advance
B11: 8081000 | C11: 43736 | D11: 49248 | E11: LIB3 | F11: USD | G11: =IF(E11="LIB1",12,IF(E11="LIB3",4,IF(E11="FED FUNDS",1,IF(E11="SOFR",4,IF(E11="Fixed",12))))) -> 4 | H11: =IF(E11="Fixed","30/360","ACT/360") -> ACT/360 | I11: =IF(E11="Fixed","LIB1","FIXED") -> FIXED | J11: USD | K11: =IF(E11="Fixed",12,G11) -> 4 | L11: =IF(I11="Fixed","30/360","ACT/360") -> 30/360 | M11: 3.375 | N11: =IF(OR(E11="SOFR",E11="FED FUNDS"),"In Arrears","In Advance") -> In Advance
B12: 355000 | C12: 44895 | D12: 47405 | E12: LIB3 | F12: USD | G12: =IF(E12="LIB1",12,IF(E12="LIB3",4,IF(E12="FED FUNDS",1,IF(E12="SOFR",4,IF(E12="Fixed",12))))) -> 4 | H12: =IF(E12="Fixed","30/360","ACT/360") -> ACT/360 | I12: =IF(E12="Fixed","LIB1","FIXED") -> FIXED | J12: USD | K12: =IF(E12="Fixed",12,G12) -> 4 | L12: =IF(I12="Fixed","30/360","ACT/360") -> 30/360 | M12: 2.798 | N12: =IF(OR(E12="SOFR",E12="FED FUNDS"),"In Arrears","In Advance") -> In Advance
B13: 2311000 | C13: 44786 | D13: 46415 | E13: SOFR | F13: USD | G13: =IF(E13="LIB1",12,IF(E13="LIB3",4,IF(E13="FED FUNDS",1,IF(E13="SOFR",4,IF(E13="Fixed",12))))) -> 4 | H13: =IF(E13="Fixed","30/360","ACT/360") -> ACT/360 | I13: =IF(E13="Fixed","LIB1","FIXED") -> FIXED | J13: USD | K13: =IF(E13="Fixed",12,G13) -> 4 | L13: =IF(I13="Fixed","30/360","ACT/360") -> 30/360 | M13: 1.768 | N13: =IF(OR(E13="SOFR",E13="FED FUNDS"),"In Arrears","In Advance") -> In Arrears
B14: 8260000 | C14: 45498 | D14: 49536 | E14: LIB3 | F14: USD | G14: =IF(E14="LIB1",12,IF(E14="LIB3",4,IF(E14="FED FUNDS",1,IF(E14="SOFR",4,IF(E14="Fixed",12))))) -> 4 | H14: =IF(E14="Fixed","30/360","ACT/360") -> ACT/360 | I14: =IF(E14="Fixed","LIB1","FIXED") -> FIXED | J14: USD | K14: =IF(E14="Fixed",12,G14) -> 4 | L14: =IF(I14="Fixed","30/360","ACT/360") -> 30/360 | M14: 3.349 | N14: =IF(OR(E14="SOFR",E14="FED FUNDS"),"In Arrears","In Advance") -> In Advance
B15: 2295000 | C15: 43589 | D15: 49100 | E15: SOFR | F15: USD | G15: =IF(E15="LIB1",12,IF(E15="LIB3",4,IF(E15="FED FUNDS",1,IF(E15="SOFR",4,IF(E15="Fixed",12))))) -> 4 | H15: =IF(E15="Fixed","30/360","ACT/360") -> ACT/360 | I15: =IF(E15="Fixed","LIB1","FIXED") -> FIXED | J15: USD | K15: =IF(E15="Fixed",12,G15) -> 4 | L15: =IF(I15="Fixed","30/360","ACT/360") -> 30/360 | M15: 4.04 | N15: =IF(OR(E15="SOFR",E15="FED FUNDS"),"In Arrears","In Advance") -> In Arrears
B16: 1512000 | C16: 43769 | D16: 49147 | E16: SOFR | F16: USD | G16: =IF(E16="LIB1",12,IF(E16="LIB3",4,IF(E16="FED FUNDS",1,IF(E16="SOFR",4,IF(E16="Fixed",12))))) -> 4 | H16: =IF(E16="Fixed","30/360","ACT/360") -> ACT/360 | I16: =IF(E16="Fixed","LIB1","FIXED") -> FIXED | J16: USD | K16: =IF(E16="Fixed",12,G16) -> 4 | L16: =IF(I16="Fixed","30/360","ACT/360") -> 30/360 | M16: 3.125 | N16: =IF(OR(E16="SOFR",E16="FED FUNDS"),"In Arrears","In Advance") -> In Arrears
B17: 7344000 | C17: 44024 | D17: 49714 | E17: LIB3 | F17: USD | G17: =IF(E17="LIB1",12,IF(E17="LIB3",4,IF(E17="FED FUNDS",1,IF(E17="SOFR",4,IF(E17="Fixed",12))))) -> 4 | H17: =IF(E17="Fixed","30/360","ACT/360") -> ACT/360 | I17: =IF(E17="Fixed","LIB1","FIXED") -> FIXED | J17: USD | K17: =IF(E17="Fixed",12,G17) -> 4 | L17: =IF(I17="Fixed","30/360","ACT/360") -> 30/360 | M17: 2.487 | N17: =IF(OR(E17="SOFR",E17="FED FUNDS"),"In Arrears","In Advance") -> In Advance
B18: 2173000 | C18: 45483 | D18: 50959 | E18: SOFR | F18: USD | G18: =IF(E18="LIB1",12,IF(E18="LIB3",4,IF(E18="FED FUNDS",1,IF(E18="SOFR",4,IF(E18="Fixed",12))))) -> 4 | H18: =IF(E18="Fixed","30/360","ACT/360") -> ACT/360 | I18: =IF(E18="Fixed","LIB1","FIXED") -> FIXED | J18: USD | K18: =IF(E18="Fixed",12,G18) -> 4 | L18: =IF(I18="Fixed","30/360","ACT/360") -> 30/360 | M18: 1.82 | N18: =IF(OR(E18="SOFR",E18="FED FUNDS"),"In Arrears","In Advance") -> In Arrears
B19: 4577000 | C19: 44310 | D19: 46240 | E19: LIB3 | F19: USD | G19: =IF(E19="LIB1",12,IF(E19="LIB3",4,IF(E19="FED FUNDS",1,IF(E19="SOFR",4,IF(E19="Fixed",12))))) -> 4 | H19: =IF(E19="Fixed","30/360","ACT/360") -> ACT/360 | I19: =IF(E19="Fixed","LIB1","FIXED") -> FIXED | J19: USD | K19: =IF(E19="Fixed",12,G19) -> 4 | L19: =IF(I19="Fixed","30/360","ACT/360") -> 30/360 | M19: 4.671 | N19: =IF(OR(E19="SOFR",E19="FED FUNDS"),"In Arrears","In Advance") -> In Advance
B20: 8569000 | C20: 45414 | D20: 50528 | E20: LIB3 | F20: USD | G20: =IF(E20="LIB1",12,IF(E20="LIB3",4,IF(E20="FED FUNDS",1,IF(E20="SOFR",4,IF(E20="Fixed",12))))) -> 4 | H20: =IF(E20="Fixed","30/360","ACT/360") -> ACT/360 | I20: =IF(E20="Fixed","LIB1","FIXED") -> FIXED | J20: USD | K20: =IF(E20="Fixed",12,G20) -> 4 | L20: =IF(I20="Fixed","30/360","ACT/360") -> 30/360 | M20: 2.643 | N20: =IF(OR(E20="SOFR",E20="FED FUNDS"),"In Arrears","In Advance") -> In Advance
B21: 2020000 | C21: 45075 | D21: 46313 | E21: FIXED | F21: USD | G21: 12 | H21: 30/360 | I21: LIB1 | J21: USD | K21: 12 | L21: ACT/360 | M21: 3.708 | N21: In Advance
B22: 8567000 | C22: 44216 | D22: 49328 | E22: FIXED | F22: USD | G22: 12 | H22: 30/360 | I22: LIB1 | J22: USD | K22: 12 | L22: ACT/360 | M22: 4.958 | N22: In Advance
B23: 5406000 | C23: 43674 | D23: 48287 | E23: FIXED | F23: USD | G23: 12 | H23: 30/360 | I23: LIB1 | J23: USD | K23: 12 | L23: ACT/360 | M23: 1.808 | N23: In Advance
B24: 6824000 | C24: 45179 | D24: 48619 | E24: FIXED | F24: USD | G24: 12 | H24: 30/360 | I24: SOFR | J24: USD | K24: 12 | L24: ACT/360 | M24: 4.764 | N24: In Arrears
B25: 8331000 | C25: 44557 | D25: 49569 | E25: FIXED | F25: USD | G25: 12 | H25: 30/360 | I25: SOFR | J25: USD | K25: 12 | L25: ACT/360 | M25: 4.002 | N25: In Arrears
B26: 407000 | C26: 43957 | D26: 46999 | E26: FIXED | F26: USD | G26: 12 | H26: 30/360 | I26: LIB1 | J26: USD | K26: 12 | L26: ACT/360 | M26: 2.651 | N26: In Advance
B27: 8905000 | C27: 45402 | D27: 48480 | E27: FIXED | F27: USD | G27: 12 | H27: 30/360 | I27: LIB1 | J27: USD | K27: 12 | L27: ACT/360 | M27: 2.205 | N27: In Advance
B28: 3385000 | C28: 44984 | D28: 47909 | E28: FIXED | F28: USD | G28: 12 | H28: 30/360 | I28: SOFR | J28: USD | K28: 12 | L28: ACT/360 | M28: 3.797 | N28: In Arrears
B29: 5072000 | C29: 44330 | D29: 47618 | E29: FIXED | F29: USD | G29: 12 | H29: 30/360 | I29: LIB1 | J29: USD | K29: 12 | L29: ACT/360 | M29: 1.044 | N29: In Advance
B30: 3977000 | C30: 44337 | D30: 49553 | E30: FIXED | F30: USD | G30: 12 | H30: 30/360 | I30: SOFR | J30: USD | K30: 12 | L30: ACT/360 | M30: 2.215 | N30: In Arrears
B31: 1101000 | C31: 44662 | D31: 46045 | E31: FIXED | F31: USD | G31: 12 | H31: 30/360 | I31: LIB1 | J31: USD | K31: 12 | L31: ACT/360 | M31: 3.336 | N31: In Advance
B32: 7826000 | C32: 44391 | D32: 49191 | E32: FED FUNDS | F32: USD | G32: =IF(E32="LIB1",12,IF(E32="LIB3",4,IF(E32="FED FUNDS",1,IF(E32="SOFR",4,IF(E32="Fixed",12))))) -> 1 | H32: =IF(E32="Fixed","30/360","ACT/360") -> ACT/360 | I32: =IF(E32="Fixed","LIB1","FIXED") -> FIXED | J32: USD | K32: =IF(E32="Fixed",12,G32) -> 1 | L32: =IF(I32="Fixed","30/360","ACT/360") -> 30/360 | M32: 4.365 | N32: =IF(OR(E32="SOFR",E32="FED FUNDS"),"In Arrears","In Advance") -> In Arrears

Sheet Userbonds
A2: Userbond | B2: Price | C2: NPV/MTM | D2: CUSIP | E2: TCKR | F2: MATDATE | G2: SECTYPE | H2: SECSUBTYPE | I2: SECSUBTYP2 | J2: RDMTYPE | K2: PAYISSDATE | L2: PAYTYPE | M2: PAYFREQ | N2: PAYDAYCOUNT | O2: PAYCRNCY | P2: PAYINDEX | Q2: PAYRESET | R2: PAYCOUPON | S2: RCVISSDATE | T2: RCVTYPE | U2: RCVFRQ | V2: RCVDAYCOUNT | W2: RCVCRNCY | X2: RCVINDEX | Y2: RCVRESET | Z2: RCVCOUPON
A3: {=[1]!YBPORT(D3,$D$2:$Z$2,D3:Z3)} -> YBP_SWAP1 | B3: {=[1]!YBPRICE(A3,"0o","Market","Price","Swap",F3,"Default","","",,"")} -> -0.03822806 | C3: =(B3/100)*Portfolio!B3 -> -3760.112 | D3: SWAP1 | E3: SWAP | F3: =Portfolio!D3 -> 46042 | G3: SWAP | H3: SWAP | I3: SWAP | J3: STANDARD | K3: =Portfolio!C3 -> 44168 | L3: FLOATING | M3: =Portfolio!G3 -> 4 | N3: =Portfolio!H3 -> ACT/360 | O3: =Portfolio!F3 -> USD | P3: =Portfolio!E3 -> SOFR | Q3: =IF(Portfolio!N3 = "In Arrears", "ARR", "ADV") -> ARR | S3: =K3 -> 44168 | T3: =IF(L3="FLOATING", "FIXED", "FLOATING") -> FIXED | U3: =Portfolio!K3 -> 4 | V3: =Portfolio!L3 -> 30/360 | W3: =Portfolio!J3 -> USD | Z3: =Portfolio!M3 -> 3.403
A4: {=[1]!YBPORT(D4,$D$2:$Z$2,D4:Z4)} -> YBP_SWAP2 | B4: {=[1]!YBPRICE(A4,"0o","Market","Price","Swap",F4,"Default","","",,"")} -> -2.2887378 | C4: =(B4/100)*Portfolio!B4 -> -122584.8 | D4: SWAP2 | E4: SWAP | F4: =Portfolio!D4 -> 49032 | G4: SWAP | H4: SWAP | I4: SWAP | J4: STANDARD | K4: =Portfolio!C4 -> 44349 | L4: =IF(Portfolio!E4="FIXED", "FIXED","FLOATING") -> FLOATING | M4: =Portfolio!G4 -> 12 | N4: =Portfolio!H4 -> ACT/360 | O4: =Portfolio!F4 -> USD | P4: =Portfolio!E4 -> LIB1 | Q4: =IF(Portfolio!N4 = "In Arrears", "ARR", "ADV") -> ADV | S4: =K4 -> 44349 | T4: =IF(L4="FLOATING", "FIXED", "FLOATING") -> FIXED | U4: =Portfolio!K4 -> 12 | V4: =Portfolio!L4 -> 30/360 | W4: =Portfolio!J4 -> USD | Z4: =Portfolio!M4 -> 3.886
A5: {=[1]!YBPORT(D5,$D$2:$Z$2,D5:Z5)} -> YBP_SWAP3 | B5: {=[1]!YBPRICE(A5,"0o","Market","Price","Swap",F5,"Default","","",,"")} -> -19.974116 | C5: =(B5/100)*Portfolio!B5 -> -1009891.3 | D5: SWAP3 | E5: SWAP | F5: =Portfolio!D5 -> 48668 | G5: SWAP | H5: SWAP | I5: SWAP | J5: STANDARD | K5: =Portfolio!C5 -> 45332 | L5: =IF(Portfolio!E5="FIXED", "FIXED","FLOATING") -> FLOATING | M5: =Portfolio!G5 -> 4 | N5: =Portfolio!H5 -> ACT/360 | O5: =Portfolio!F5 -> USD | P5: =Portfolio!E5 -> LIB3 | Q5: =IF(Portfolio!N5 = "In Arrears", "ARR", "ADV") -> ADV | S5: =K5 -> 45332 | T5: =IF(L5="FLOATING", "FIXED", "FLOATING") -> FIXED | U5: =Portfolio!K5 -> 4 | V5: =Portfolio!L5 -> 30/360 | W5: =Portfolio!J5 -> USD | Z5: =Portfolio!M5 -> 1.055
A6: {=[1]!YBPORT(D6,$D$2:$Z$2,D6:Z6)} -> YBP_SWAP4 | B6: {=[1]!YBPRICE(A6,"0o","Market","Price","Swap",F6,"Default","","",,"")} -> -2.1351268 | C6: =(B6/100)*Portfolio!B6 -> -206808.38 | D6: SWAP4 | E6: SWAP | F6: =Portfolio!D6 -> 50928 | G6: SWAP | H6: SWAP | I6: SWAP | J6: STANDARD | K6: =Portfolio!C6 -> 45469 | L6: =IF(Portfolio!E6="FIXED", "FIXED","FLOATING") -> FLOATING | M6: =Portfolio!G6 -> 1 | N6: =Portfolio!H6 -> ACT/360 | O6: =Portfolio!F6 -> USD | P6: =Portfolio!E6 -> FED FUNDS | Q6: =IF(Portfolio!N6 = "In Arrears", "ARR", "ADV") -> ARR | S6: =K6 -> 45469 | T6: =IF(L6="FLOATING", "FIXED", "FLOATING") -> FIXED | U6: =Portfolio!K6 -> 1 | V6: =Portfolio!L6 -> 30/360 | W6: =Portfolio!J6 -> USD | Z6: =Portfolio!M6 -> 4.482
A7: {=[1]!YBPORT(D7,$D$2:$Z$2,D7:Z7)} -> YBP_SWAP5 | B7: {=[1]!YBPRICE(A7,"0o","Market","Price","Swap",F7,"Default","","",,"")} -> 6.1318173 | C7: =(B7/100)*Portfolio!B7 -> 418312.58 | D7: SWAP5 | E7: SWAP | F7: =Portfolio!D7 -> 47691 | G7: SWAP | H7: SWAP | I7: SWAP | J7: STANDARD | K7: =Portfolio!C7 -> 44478 | L7: =IF(Portfolio!E7="FIXED", "FIXED","FLOATING") -> FIXED | M7: =Portfolio!G7 -> 12 | N7: =Portfolio!H7 -> 30/360 | O7: =Portfolio!F7 -> USD | R7: =Portfolio!M7 -> 1.958 | S7: =K7 -> 44478 | T7: =IF(L7="FLOATING", "FIXED", "FLOATING") -> FLOATING | U7: =Portfolio!K7 -> 12 | V7: =Portfolio!L7 -> ACT/360 | W7: =Portfolio!J7 -> USD | X7: =Portfolio!I7 -> SOFR | Y7: =IF(Portfolio!N7="In Arrears", "ARR", "ADV") -> ARR
A8: {=[1]!YBPORT(D8,$D$2:$Z$2,D8:Z8)} -> YBP_SWAP6 | B8: {=[1]!YBPRICE(A8,"0o","Market","Price","Swap",F8,"Default","","",,"")} -> 48.527362 | C8: =(B8/100)*Portfolio!B8 -> 1808614.8 | D8: SWAP6 | E8: SWAP | F8: =Portfolio!D8 -> 49542 | G8: SWAP | H8: SWAP | I8: SWAP | J8: STANDARD | K8: =Portfolio!C8 -> 44372 | L8: =IF(Portfolio!E8="FIXED", "FIXED","FLOATING") -> FIXED | M8: =Portfolio!G8 -> 12 | N8: =Portfolio!H8 -> 30/360 | O8: =Portfolio!F8 -> USD | R8: =Portfolio!M8 -> 2.143 | S8: =K8 -> 44372 | T8: =IF(L8="FLOATING", "FIXED", "FLOATING") -> FLOATING | U8: =Portfolio!K8 -> 12 | V8: =Portfolio!L8 -> ACT/360 | W8: =Portfolio!J8 -> USD | X8: =Portfolio!I8 -> LIB1 | Y8: =IF(Portfolio!N8="In Arrears", "ARR", "ADV") -> ADV
A9: {=[1]!YBPORT(D9,$D$2:$Z$2,D9:Z9)} -> YBP_SWAP7 | B9: {=[1]!YBPRICE(A9,"0o","Market","Price","Swap",F9,"Default","","",,"")} -> -0.1768677 | C9: =(B9/100)*Portfolio!B9 -> -5764.1183 | D9: SWAP7 | E9: SWAP | F9: =Portfolio!D9 -> 46122 | G9: SWAP | H9: SWAP | I9: SWAP | J9: STANDARD | K9: =Portfolio!C9 -> 44147 | L9: =IF(Portfolio!E9="FIXED", "FIXED","FLOATING") -> FIXED | M9: =Portfolio!G9 -> 12 | N9: =Portfolio!H9 -> 30/360 | O9: =Portfolio!F9 -> USD | R9: =Portfolio!M9 -> 4.241 | S9: =K9 -> 44147 | T9: =IF(L9="FLOATING", "FIXED", "FLOATING") -> FLOATING | U9: =Portfolio!K9 -> 12 | V9: =Portfolio!L9 -> ACT/360 | W9: =Portfolio!J9 -> USD | X9: =Portfolio!I9 -> SOFR | Y9: =IF(Portfolio!N9="In Arrears", "ARR", "ADV") -> ARR
A10: {=[1]!YBPORT(D10,$D$2:$Z$2,D10:Z10)} -> YBP_SWAP8 | B10: {=[1]!YBPRICE(A10,"0o","Market","Price","Swap",F10,"Default","","",,"")} -> 16.87504 | C10: =(B10/100)*Portfolio!B10 -> 148500.35 | D10: SWAP8 | E10: SWAP | F10: =Portfolio!D10 -> 47491 | G10: SWAP | H10: SWAP | I10: SWAP | J10: STANDARD | K10: =Portfolio!C10 -> 45163 | L10: =IF(Portfolio!E10="FIXED", "FIXED","FLOATING") -> FIXED | M10: =Portfolio!G10 -> 12 | N10: =Portfolio!H10 -> 30/360 | O10: =Portfolio!F10 -> USD | R10: =Portfolio!M10 -> 2.899 | S10: =K10 -> 45163 | T10: =IF(L10="FLOATING", "FIXED", "FLOATING") -> FLOATING | U10: =Portfolio!K10 -> 12 | V10: =Portfolio!L10 -> ACT/360 | W10: =Portfolio!J10 -> USD | X10: =Portfolio!I10 -> LIB1 | Y10: =IF(Portfolio!N10="In Arrears", "ARR", "ADV") -> ADV
A11: {=[1]!YBPORT(D11,$D$2:$Z$2,D11:Z11)} -> YBP_SWAP9 | B11: {=[1]!YBPRICE(A11,"0o","Market","Price","Swap",F11,"Default","","",,"")} -> -7.1984395 | C11: =(B11/100)*Portfolio!B11 -> -581705.9 | D11: SWAP9 | E11: SWAP | F11: =Portfolio!D11 -> 49248 | G11: SWAP | H11: SWAP | I11: SWAP | J11: STANDARD | K11: =Portfolio!C11 -> 43736 | L11: =IF(Portfolio!E11="FIXED", "FIXED","FLOATING") -> FLOATING | M11: =Portfolio!G11 -> 4 | N11: =Portfolio!H11 -> ACT/360 | O11: =Portfolio!F11 -> USD | P11: =Portfolio!E11 -> LIB3 | Q11: =IF(Portfolio!N11 = "In Arrears", "ARR", "ADV") -> ADV | S11: =K11 -> 43736 | T11: =IF(L11="FLOATING", "FIXED", "FLOATING") -> FIXED | U11: =Portfolio!K11 -> 4 | V11: =Portfolio!L11 -> 30/360 | W11: =Portfolio!J11 -> USD | Z11: =Portfolio!M11 -> 3.375
A12: {=[1]!YBPORT(D12,$D$2:$Z$2,D12:Z12)} -> YBP_SWAP10 | B12: {=[1]!YBPRICE(A12,"0o","Market","Price","Swap",F12,"Default","","",,"")} -> -4.0261408 | C12: =(B12/100)*Portfolio!B12 -> -14292.8 | D12: SWAP10 | E12: SWAP | F12: =Portfolio!D12 -> 47405 | G12: SWAP | H12: SWAP | I12: SWAP | J12: STANDARD | K12: =Portfolio!C12 -> 44895 | L12: =IF(Portfolio!E12="FIXED", "FIXED","FLOATING") -> FLOATING | M12: =Portfolio!G12 -> 4 | N12: =Portfolio!H12 -> ACT/360 | O12: =Portfolio!F12 -> USD | P12: =Portfolio!E12 -> LIB3 | Q12: =IF(Portfolio!N12 = "In Arrears", "ARR", "ADV") -> ADV | S12: =K12 -> 44895 | T12: =IF(L12="FLOATING", "FIXED", "FLOATING") -> FIXED | U12: =Portfolio!K12 -> 4 | V12: =Portfolio!L12 -> 30/360 | W12: =Portfolio!J12 -> USD | Z12: =Portfolio!M12 -> 2.798
A13: {=[1]!YBPORT(D13,$D$2:$Z$2,D13:Z13)} -> YBP_SWAP11 | B13: {=[1]!YBPRICE(A13,"0o","Market","Price","Swap",F13,"Default","","",,"")} -> -1.8472074 | C13: =(B13/100)*Portfolio!B13 -> -42688.963 | D13: SWAP11 | E13: SWAP | F13: =Portfolio!D13 -> 46415 | G13: SWAP | H13: SWAP | I13: SWAP | J13: STANDARD | K13: =Portfolio!C13 -> 44786 | L13: =IF(Portfolio!E13="FIXED", "FIXED","FLOATING") -> FLOATING | M13: =Portfolio!G13 -> 4 | N13: =Portfolio!H13 -> ACT/360 | O13: =Portfolio!F13 -> USD | P13: =Portfolio!E13 -> SOFR | Q13: =IF(Portfolio!N13 = "In Arrears", "ARR", "ADV") -> ARR | S13: =K13 -> 44786 | T13: =IF(L13="FLOATING", "FIXED", "FLOATING") -> FIXED | U13: =Portfolio!K13 -> 4 | V13: =Portfolio!L13 -> 30/360 | W13: =Portfolio!J13 -> USD | Z13: =Portfolio!M13 -> 1.768
A14: {=[1]!YBPORT(D14,$D$2:$Z$2,D14:Z14)} -> YBP_SWAP12 | B14: {=[1]!YBPRICE(A14,"0o","Market","Price","Swap",F14,"Default","","",,"")} -> -8.4183487 | C14: =(B14/100)*Portfolio!B14 -> -695355.6 | D14: SWAP12 | E14: SWAP | F14: =Portfolio!D14 -> 49536 | G14: SWAP | H14: SWAP | I14: SWAP | J14: STANDARD | K14: =Portfolio!C14 -> 45498 | L14: =IF(Portfolio!E14="FIXED", "FIXED","FLOATING") -> FLOATING | M14: =Portfolio!G14 -> 4 | N14: =Portfolio!H14 -> ACT/360 | O14: =Portfolio!F14 -> USD | P14: =Portfolio!E14 -> LIB3 | Q14: =IF(Portfolio!N14 = "In Arrears", "ARR", "ADV") -> ADV | S14: =K14 -> 45498 | T14: =IF(L14="FLOATING", "FIXED", "FLOATING") -> FIXED | U14: =Portfolio!K14 -> 4 | V14: =Portfolio!L14 -> 30/360 | W14: =Portfolio!J14 -> USD | Z14: =Portfolio!M14 -> 3.349
A15: {=[1]!YBPORT(D15,$D$2:$Z$2,D15:Z15)} -> YBP_SWAP13 | B15: {=[1]!YBPRICE(A15,"0o","Market","Price","Swap",F15,"Default","","",,"")} -> 2.8284436 | C15: =(B15/100)*Portfolio!B15 -> 64912.78 | D15: SWAP13 | E15: SWAP | F15: =Portfolio!D15 -> 49100 | G15: SWAP | H15: SWAP | I15: SWAP | J15: STANDARD | K15: =Portfolio!C15 -> 43589 | L15: =IF(Portfolio!E15="FIXED", "FIXED","FLOATING") -> FLOATING | M15: =Portfolio!G15 -> 4 | N15: =Portfolio!H15 -> ACT/360 | O15: =Portfolio!F15 -> USD | P15: =Portfolio!E15 -> SOFR | Q15: =IF(Portfolio!N15 = "In Arrears", "ARR", "ADV") -> ARR | S15: =K15 -> 43589 | T15: =IF(L15="FLOATING", "FIXED", "FLOATING") -> FIXED | U15: =Portfolio!K15 -> 4 | V15: =Portfolio!L15 -> 30/360 | W15: =Portfolio!J15 -> USD | Z15: =Portfolio!M15 -> 4.04
A16: {=[1]!YBPORT(D16,$D$2:$Z$2,D16:Z16)} -> YBP_SWAP14 | B16: {=[1]!YBPRICE(A16,"0o","Market","Price","Swap",F16,"Default","","",,"")} -> -3.7837699 | C16: =(B16/100)*Portfolio!B16 -> -57210.601 | D16: SWAP14 | E16: SWAP | F16: =Portfolio!D16 -> 49147 | G16: SWAP | H16: SWAP | I16: SWAP | J16: STANDARD | K16: =Portfolio!C16 -> 43769 | L16: =IF(Portfolio!E16="FIXED", "FIXED","FLOATING") -> FLOATING | M16: =Portfolio!G16 -> 4 | N16: =Portfolio!H16 -> ACT/360 | O16: =Portfolio!F16 -> USD | P16: =Portfolio!E16 -> SOFR | Q16: =IF(Portfolio!N16 = "In Arrears", "ARR", "ADV") -> ARR | S16: =K16 -> 43769 | T16: =IF(L16="FLOATING", "FIXED", "FLOATING") -> FIXED | U16: =Portfolio!K16 -> 4 | V16: =Portfolio!L16 -> 30/360 | W16: =Portfolio!J16 -> USD | Z16: =Portfolio!M16 -> 3.125
A17: {=[1]!YBPORT(D17,$D$2:$Z$2,D17:Z17)} -> YBP_SWAP15 | B17: {=[1]!YBPRICE(A17,"0o","Market","Price","Swap",F17,"Default","","",,"")} -> -16.142123 | C17: =(B17/100)*Portfolio!B17 -> -1185477.5 | D17: SWAP15 | E17: SWAP | F17: =Portfolio!D17 -> 49714 | G17: SWAP | H17: SWAP | I17: SWAP | J17: STANDARD | K17: =Portfolio!C17 -> 44024 | L17: =IF(Portfolio!E17="FIXED", "FIXED","FLOATING") -> FLOATING | M17: =Portfolio!G17 -> 4 | N17: =Portfolio!H17 -> ACT/360 | O17: =Portfolio!F17 -> USD | P17: =Portfolio!E17 -> LIB3 | Q17: =IF(Portfolio!N17 = "In Arrears", "ARR", "ADV") -> ADV | S17: =K17 -> 44024 | T17: =IF(L17="FLOATING", "FIXED", "FLOATING") -> FIXED | U17: =Portfolio!K17 -> 4 | V17: =Portfolio!L17 -> 30/360 | W17: =Portfolio!J17 -> USD | Z17: =Portfolio!M17 -> 2.487
A18: {=[1]!YBPORT(D18,$D$2:$Z$2,D18:Z18)} -> YBP_SWAP16 | B18: {=[1]!YBPRICE(A18,"0o","Market","Price","Swap",F18,"Default","","",,"")} -> -21.236818 | C18: =(B18/100)*Portfolio!B18 -> -461476.06 | D18: SWAP16 | E18: SWAP | F18: =Portfolio!D18 -> 50959 | G18: SWAP | H18: SWAP | I18: SWAP | J18: STANDARD | K18: =Portfolio!C18 -> 45483 | L18: =IF(Portfolio!E18="FIXED", "FIXED","FLOATING") -> FLOATING | M18: =Portfolio!G18 -> 4 | N18: =Portfolio!H18 -> ACT/360 | O18: =Portfolio!F18 -> USD | P18: =Portfolio!E18 -> SOFR | Q18: =IF(Portfolio!N18 = "In Arrears", "ARR", "ADV") -> ARR | S18: =K18 -> 45483 | T18: =IF(L18="FLOATING", "FIXED", "FLOATING") -> FIXED | U18: =Portfolio!K18 -> 4 | V18: =Portfolio!L18 -> 30/360 | W18: =Portfolio!J18 -> USD | Z18: =Portfolio!M18 -> 1.82
A19: {=[1]!YBPORT(D19,$D$2:$Z$2,D19:Z19)} -> YBP_SWAP17 | B19: {=[1]!YBPRICE(A19,"0o","Market","Price","Swap",F19,"Default","","",,"")} -> 0.44421843 | C19: =(B19/100)*Portfolio!B19 -> 20331.878 | D19: SWAP17 | E19: SWAP | F19: =Portfolio!D19 -> 46240 | G19: SWAP | H19: SWAP | I19: SWAP | J19: STANDARD | K19: =Portfolio!C19 -> 44310 | L19: =IF(Portfolio!E19="FIXED", "FIXED","FLOATING") -> FLOATING | M19: =Portfolio!G19 -> 4 | N19: =Portfolio!H19 -> ACT/360 | O19: =Portfolio!F19 -> USD | P19: =Portfolio!E19 -> LIB3 | Q19: =IF(Portfolio!N19 = "In Arrears", "ARR", "ADV") -> ADV | S19: =K19 -> 44310 | T19: =IF(L19="FLOATING", "FIXED", "FLOATING") -> FIXED | U19: =Portfolio!K19 -> 4 | V19: =Portfolio!L19 -> 30/360 | W19: =Portfolio!J19 -> USD | Z19: =Portfolio!M19 -> 4.671
A20: {=[1]!YBPORT(D20,$D$2:$Z$2,D20:Z20)} -> YBP_SWAP18 | B20: {=[1]!YBPRICE(A20,"0o","Market","Price","Swap",F20,"Default","","",,"")} -> -18.524428 | C20: =(B20/100)*Portfolio!B20 -> -1587358.2 | D20: SWAP18 | E20: SWAP | F20: =Portfolio!D20 -> 50528 | G20: SWAP | H20: SWAP | I20: SWAP | J20: STANDARD | K20: =Portfolio!C20 -> 45414 | L20: =IF(Portfolio!E20="FIXED", "FIXED","FLOATING") -> FLOATING | M20: =Portfolio!G20 -> 4 | N20: =Portfolio!H20 -> ACT/360 | O20: =Portfolio!F20 -> USD | P20: =Portfolio!E20 -> LIB3 | Q20: =IF(Portfolio!N20 = "In Arrears", "ARR", "ADV") -> ADV | S20: =K20 -> 45414 | T20: =IF(L20="FLOATING", "FIXED", "FLOATING") -> FIXED | U20: =Portfolio!K20 -> 4 | V20: =Portfolio!L20 -> 30/360 | W20: =Portfolio!J20 -> USD | Z20: =Portfolio!M20 -> 2.643
A21: {=[1]!YBPORT(D21,$D$2:$Z$2,D21:Z21)} -> YBP_SWAP19 | B21: {=[1]!YBPRICE(A21,"0o","Market","Price","Swap",F21,"Default","","",,"")} -> -0.16616794 | C21: =(B21/100)*Portfolio!B21 -> -3356.5924 | D21: SWAP19 | E21: SWAP | F21: =Portfolio!D21 -> 46313 | G21: SWAP | H21: SWAP | I21: SWAP | J21: STANDARD | K21: =Portfolio!C21 -> 45075 | L21: =IF(Portfolio!E21="FIXED", "FIXED","FLOATING") -> FIXED | M21: =Portfolio!G21 -> 12 | N21: =Portfolio!H21 -> 30/360 | O21: =Portfolio!F21 -> USD | R21: =Portfolio!M21 -> 3.708 | S21: =K21 -> 45075 | T21: =IF(L21="FLOATING", "FIXED", "FLOATING") -> FLOATING | U21: =Portfolio!K21 -> 12 | V21: =Portfolio!L21 -> ACT/360 | W21: =Portfolio!J21 -> USD | X21: =Portfolio!I21 -> LIB1 | Y21: =IF(Portfolio!N21="In Arrears", "ARR", "ADV") -> ADV
A22: {=[1]!YBPORT(D22,$D$2:$Z$2,D22:Z22)} -> YBP_SWAP20 | B22: {=[1]!YBPRICE(A22,"0o","Market","Price","Swap",F22,"Default","","",,"")} -> 24.318018 | C22: =(B22/100)*Portfolio!B22 -> 2083324.6 | D22: SWAP20 | E22: SWAP | F22: =Portfolio!D22 -> 49328 | G22: SWAP | H22: SWAP | I22: SWAP | J22: STANDARD | K22: =Portfolio!C22 -> 44216 | L22: =IF(Portfolio!E22="FIXED", "FIXED","FLOATING") -> FIXED | M22: =Portfolio!G22 -> 12 | N22: =Portfolio!H22 -> 30/360 | O22: =Portfolio!F22 -> USD | R22: =Portfolio!M22 -> 4.958 | S22: =K22 -> 44216 | T22: =IF(L22="FLOATING", "FIXED", "FLOATING") -> FLOATING | U22: =Portfolio!K22 -> 12 | V22: =Portfolio!L22 -> ACT/360 | W22: =Portfolio!J22 -> USD | X22: =Portfolio!I22 -> LIB1 | Y22: =IF(Portfolio!N22="In Arrears", "ARR", "ADV") -> ADV
A23: {=[1]!YBPORT(D23,$D$2:$Z$2,D23:Z23)} -> YBP_SWAP21 | B23: {=[1]!YBPRICE(A23,"0o","Market","Price","Swap",F23,"Default","","",,"")} -> 32.650011 | C23: =(B23/100)*Portfolio!B23 -> 1765059.6 | D23: SWAP21 | E23: SWAP | F23: =Portfolio!D23 -> 48287 | G23: SWAP | H23: SWAP | I23: SWAP | J23: STANDARD | K23: =Portfolio!C23 -> 43674 | L23: =IF(Portfolio!E23="FIXED", "FIXED","FLOATING") -> FIXED | M23: =Portfolio!G23 -> 12 | N23: =Portfolio!H23 -> 30/360 | O23: =Portfolio!F23 -> USD | R23: =Portfolio!M23 -> 1.808 | S23: =K23 -> 43674 | T23: =IF(L23="FLOATING", "FIXED", "FLOATING") -> FLOATING | U23: =Portfolio!K23 -> 12 | V23: =Portfolio!L23 -> ACT/360 | W23: =Portfolio!J23 -> USD | X23: =Portfolio!I23 -> LIB1 | Y23: =IF(Portfolio!N23="In Arrears", "ARR", "ADV") -> ADV
A24: {=[1]!YBPORT(D24,$D$2:$Z$2,D24:Z24)} -> YBP_SWAP22 | B24: {=[1]!YBPRICE(A24,"0o","Market","Price","Swap",F24,"Default","","",,"")} -> -7.4781134 | C24: =(B24/100)*Portfolio!B24 -> -510306.46 | D24: SWAP22 | E24: SWAP | F24: =Portfolio!D24 -> 48619 | G24: SWAP | H24: SWAP | I24: SWAP | J24: STANDARD | K24: =Portfolio!C24 -> 45179 | L24: =IF(Portfolio!E24="FIXED", "FIXED","FLOATING") -> FIXED | M24: =Portfolio!G24 -> 12 | N24: =Portfolio!H24 -> 30/360 | O24: =Portfolio!F24 -> USD | R24: =Portfolio!M24 -> 4.764 | S24: =K24 -> 45179 | T24: =IF(L24="FLOATING", "FIXED", "FLOATING") -> FLOATING | U24: =Portfolio!K24 -> 12 | V24: =Portfolio!L24 -> ACT/360 | W24: =Portfolio!J24 -> USD | X24: =Portfolio!I24 -> SOFR | Y24: =IF(Portfolio!N24="In Arrears", "ARR", "ADV") -> ARR
A25: {=[1]!YBPORT(D25,$D$2:$Z$2,D25:Z25)} -> YBP_SWAP23 | B25: {=[1]!YBPRICE(A25,"0o","Market","Price","Swap",F25,"Default","","",,"")} -> -2.3806561 | C25: =(B25/100)*Portfolio!B25 -> -198332.46 | D25: SWAP23 | E25: SWAP | F25: =Portfolio!D25 -> 49569 | G25: SWAP | H25: SWAP | I25: SWAP | J25: STANDARD | K25: =Portfolio!C25 -> 44557 | L25: =IF(Portfolio!E25="FIXED", "FIXED","FLOATING") -> FIXED | M25: =Portfolio!G25 -> 12 | N25: =Portfolio!H25 -> 30/360 | O25: =Portfolio!F25 -> USD | R25: =Portfolio!M25 -> 4.002 | S25: =K25 -> 44557 | T25: =IF(L25="FLOATING", "FIXED", "FLOATING") -> FLOATING | U25: =Portfolio!K25 -> 12 | V25: =Portfolio!L25 -> ACT/360 | W25: =Portfolio!J25 -> USD | X25: =Portfolio!I25 -> SOFR | Y25: =IF(Portfolio!N25="In Arrears", "ARR", "ADV") -> ARR
A26: {=[1]!YBPORT(D26,$D$2:$Z$2,D26:Z26)} -> YBP_SWAP24 | B26: {=[1]!YBPRICE(A26,"0o","Market","Price","Swap",F26,"Default","","",,"")} -> 11.820928 | C26: =(B26/100)*Portfolio!B26 -> 48111.175 | D26: SWAP24 | E26: SWAP | F26: =Portfolio!D26 -> 46999 | G26: SWAP | H26: SWAP | I26: SWAP | J26: STANDARD | K26: =Portfolio!C26 -> 43957 | L26: =IF(Portfolio!E26="FIXED", "FIXED","FLOATING") -> FIXED | M26: =Portfolio!G26 -> 12 | N26: =Portfolio!H26 -> 30/360 | O26: =Portfolio!F26 -> USD | R26: =Portfolio!M26 -> 2.651 | S26: =K26 -> 43957 | T26: =IF(L26="FLOATING", "FIXED", "FLOATING") -> FLOATING | U26: =Portfolio!K26 -> 12 | V26: =Portfolio!L26 -> ACT/360 | W26: =Portfolio!J26 -> USD | X26: =Portfolio!I26 -> LIB1 | Y26: =IF(Portfolio!N26="In Arrears", "ARR", "ADV") -> ADV
A27: {=[1]!YBPORT(D27,$D$2:$Z$2,D27:Z27)} -> YBP_SWAP25 | B27: {=[1]!YBPRICE(A27,"0o","Market","Price","Swap",F27,"Default","","",,"")} -> 33.42689 | C27: =(B27/100)*Portfolio!B27 -> 2976664.6 | D27: SWAP25 | E27: SWAP | F27: =Portfolio!D27 -> 48480 | G27: SWAP | H27: SWAP | I27: SWAP | J27: STANDARD | K27: =Portfolio!C27 -> 45402 | L27: =IF(Portfolio!E27="FIXED", "FIXED","FLOATING") -> FIXED | M27: =Portfolio!G27 -> 12 | N27: =Portfolio!H27 -> 30/360 | O27: =Portfolio!F27 -> USD | R27: =Portfolio!M27 -> 2.205 | S27: =K27 -> 45402 | T27: =IF(L27="FLOATING", "FIXED", "FLOATING") -> FLOATING | U27: =Portfolio!K27 -> 12 | V27: =Portfolio!L27 -> ACT/360 | W27: =Portfolio!J27 -> USD | X27: =Portfolio!I27 -> LIB1 | Y27: =IF(Portfolio!N27="In Arrears", "ARR", "ADV") -> ADV
A28: {=[1]!YBPORT(D28,$D$2:$Z$2,D28:Z28)} -> YBP_SWAP26 | B28: {=[1]!YBPRICE(A28,"0o","Market","Price","Swap",F28,"Default","","",,"")} -> -1.6808424 | C28: =(B28/100)*Portfolio!B28 -> -56896.514 | D28: SWAP26 | E28: SWAP | F28: =Portfolio!D28 -> 47909 | G28: SWAP | H28: SWAP | I28: SWAP | J28: STANDARD | K28: =Portfolio!C28 -> 44984 | L28: =IF(Portfolio!E28="FIXED", "FIXED","FLOATING") -> FIXED | M28: =Portfolio!G28 -> 12 | N28: =Portfolio!H28 -> 30/360 | O28: =Portfolio!F28 -> USD | R28: =Portfolio!M28 -> 3.797 | S28: =K28 -> 44984 | T28: =IF(L28="FLOATING", "FIXED", "FLOATING") -> FLOATING | U28: =Portfolio!K28 -> 12 | V28: =Portfolio!L28 -> ACT/360 | W28: =Portfolio!J28 -> USD | X28: =Portfolio!I28 -> SOFR | Y28: =IF(Portfolio!N28="In Arrears", "ARR", "ADV") -> ARR
A29: {=[1]!YBPORT(D29,$D$2:$Z$2,D29:Z29)} -> YBP_SWAP27 | B29: {=[1]!YBPRICE(A29,"0o","Market","Price","Swap",F29,"Default","","",,"")} -> 8.685081 | C29: =(B29/100)*Portfolio!B29 -> 440507.31 | D29: SWAP27 | E29: SWAP | F29: =Portfolio!D29 -> 47618 | G29: SWAP | H29: SWAP | I29: SWAP | J29: STANDARD | K29: =Portfolio!C29 -> 44330 | L29: =IF(Portfolio!E29="FIXED", "FIXED","FLOATING") -> FIXED | M29: =Portfolio!G29 -> 12 | N29: =Portfolio!H29 -> 30/360 | O29: =Portfolio!F29 -> USD | R29: =Portfolio!M29 -> 1.044 | S29: =K29 -> 44330 | T29: =IF(L29="FLOATING", "FIXED", "FLOATING") -> FLOATING | U29: =Portfolio!K29 -> 12 | V29: =Portfolio!L29 -> ACT/360 | W29: =Portfolio!J29 -> USD | X29: =Portfolio!I29 -> LIB1 | Y29: =IF(Portfolio!N29="In Arrears", "ARR", "ADV") -> ADV
A30: {=[1]!YBPORT(D30,$D$2:$Z$2,D30:Z30)} -> YBP_SWAP28 | B30: {=[1]!YBPRICE(A30,"0o","Market","Price","Swap",F30,"Default","","",,"")} -> 11.873296 | C30: =(B30/100)*Portfolio!B30 -> 472200.97 | D30: SWAP28 | E30: SWAP | F30: =Portfolio!D30 -> 49553 | G30: SWAP | H30: SWAP | I30: SWAP | J30: STANDARD | K30: =Portfolio!C30 -> 44337 | L30: =IF(Portfolio!E30="FIXED", "FIXED","FLOATING") -> FIXED | M30: =Portfolio!G30 -> 12 | N30: =Portfolio!H30 -> 30/360 | O30: =Portfolio!F30 -> USD | R30: =Portfolio!M30 -> 2.215 | S30: =K30 -> 44337 | T30: =IF(L30="FLOATING", "FIXED", "FLOATING") -> FLOATING | U30: =Portfolio!K30 -> 12 | V30: =Portfolio!L30 -> ACT/360 | W30: =Portfolio!J30 -> USD | X30: =Portfolio!I30 -> SOFR | Y30: =IF(Portfolio!N30="In Arrears", "ARR", "ADV") -> ARR
A31: {=[1]!YBPORT(D31,$D$2:$Z$2,D31:Z31)} -> YBP_SWAP29 | B31: {=[1]!YBPRICE(A31,"0o","Market","Price","Swap",F31,"Default","","",,"")} -> 0.40864049 | C31: =(B31/100)*Portfolio!B31 -> 4499.1318 | D31: SWAP29 | E31: SWAP | F31: =Portfolio!D31 -> 46045 | G31: SWAP | H31: SWAP | I31: SWAP | J31: STANDARD | K31: =Portfolio!C31 -> 44662 | L31: =IF(Portfolio!E31="FIXED", "FIXED","FLOATING") -> FIXED | M31: =Portfolio!G31 -> 12 | N31: =Portfolio!H31 -> 30/360 | O31: =Portfolio!F31 -> USD | R31: =Portfolio!M31 -> 3.336 | S31: =K31 -> 44662 | T31: =IF(L31="FLOATING", "FIXED", "FLOATING") -> FLOATING | U31: =Portfolio!K31 -> 12 | V31: =Portfolio!L31 -> ACT/360 | W31: =Portfolio!J31 -> USD | X31: =Portfolio!I31 -> LIB1 | Y31: =IF(Portfolio!N31="In Arrears", "ARR", "ADV") -> ADV
A32: {=[1]!YBPORT(D32,$D$2:$Z$2,D32:Z32)} -> YBP_SWAP30 | B32: {=[1]!YBPRICE(A32,"0o","Market","Price","Swap",F32,"Default","","",,"")} -> -0.37460868 | C32: =(B32/100)*Portfolio!B32 -> -29316.875 | D32: SWAP30 | E32: SWAP | F32: =Portfolio!D32 -> 49191 | G32: SWAP | H32: SWAP | I32: SWAP | J32: STANDARD | K32: =Portfolio!C32 -> 44391 | L32: =IF(Portfolio!E32="FIXED", "FIXED","FLOATING") -> FLOATING | M32: =Portfolio!G32 -> 1 | N32: =Portfolio!H32 -> ACT/360 | O32: =Portfolio!F32 -> USD | P32: =Portfolio!E32 -> FED FUNDS | Q32: =IF(Portfolio!N32 = "In Arrears", "ARR", "ADV") -> ARR | R32: =Portfolio!M32 -> 4.365 | S32: =K32 -> 44391 | T32: =IF(L32="FLOATING", "FIXED", "FLOATING") -> FIXED | U32: =Portfolio!K32 -> 1 | V32: =Portfolio!L32 -> 30/360 | W32: =Portfolio!J32 -> USD | Z32: =Portfolio!M32 -> 4.365

Sheet Part 1 - Portfolio
A1: Part 1: insert your trades as user bonds, you need to have 11 valuation dates
A2: Hint: I would put the dates up top and the portfolio horizontal below
A4: Dates | B4: 45688 | C4: 45716 | D4: 45747 | E4: 45777 | F4: 45807 | G4: 45838 | H4: 45869 | I4: 45898 | J4: 45930 | K4: 45961 | L4: 45989
A5: =[2]Userbonds!A3 -> YBP_SWAP1 | B5: {=[1]!YBPRICE($A5,"0o",B$4,"Price","Swap",B$4,"Default","","",,"")} -> -0.72891029 | C5: {=[1]!YBPRICE($A5,"0o",C$4,"Price","Swap",C$4,"Default","","",,"")} -> -0.58874941 | D5: {=[1]!YBPRICE($A5,"0o",D$4,"Price","Swap",D$4,"Default","","",,"")} -> -0.52827036 | E5: {=[1]!YBPRICE($A5,"0o",E$4,"Price","Swap",E$4,"Default","","",,"")} -> -0.38799364 | F5: {=[1]!YBPRICE($A5,"0o",F$4,"Price","Swap",F$4,"Default","","",,"")} -> -0.52207364 | G5: {=[1]!YBPRICE($A5,"0o",G$4,"Price","Swap",G$4,"Default","","",,"")} -> -0.41352013 | H5: {=[1]!YBPRICE($A5,"0o",H$4,"Price","Swap",H$4,"Default","","",,"")} -> -0.42014 | I5: {=[1]!YBPRICE($A5,"0o",I$4,"Price","Swap",I$4,"Default","","",,"")} -> -0.27858518 | ... L5: {=[1]!YBPRICE($A5,"0o",L$4,"Price","Swap",L$4,"Default","","",,"")} -> -0.06239403
A6: =[2]Userbonds!A4 -> YBP_SWAP2 | B6: {=[1]!YBPRICE($A6,"0o",B$4,"Price","Swap",B$4,"Default","","",,"")} -> -2.2521258 | C6: {=[1]!YBPRICE($A6,"0o",C$4,"Price","Swap",C$4,"Default","","",,"")} -> 0.07487872 | D6: {=[1]!YBPRICE($A6,"0o",D$4,"Price","Swap",D$4,"Default","","",,"")} -> 0.17380645 | E6: {=[1]!YBPRICE($A6,"0o",E$4,"Price","Swap",E$4,"Default","","",,"")} -> 1.4764697 | F6: {=[1]!YBPRICE($A6,"0o",F$4,"Price","Swap",F$4,"Default","","",,"")} -> -0.13971484 | G6: {=[1]!YBPRICE($A6,"0o",G$4,"Price","Swap",G$4,"Default","","",,"")} -> 1.23178 | H6: {=[1]!YBPRICE($A6,"0o",H$4,"Price","Swap",H$4,"Default","","",,"")} -> 0.22534619 | I6: {=[1]!YBPRICE($A6,"0o",I$4,"Price","Swap",I$4,"Default","","",,"")} -> 1.4503465 | ... L6: {=[1]!YBPRICE($A6,"0o",L$4,"Price","Swap",L$4,"Default","","",,"")} -> 2.0244381
A7: =[2]Userbonds!A5 -> YBP_SWAP3 | B7: {=[1]!YBPRICE($A7,"0o",B$4,"Price","Swap",B$4,"Default","","",,"")} -> -22.562728 | C7: {=[1]!YBPRICE($A7,"0o",C$4,"Price","Swap",C$4,"Default","","",,"")} -> -20.481334 | D7: {=[1]!YBPRICE($A7,"0o",D$4,"Price","Swap",D$4,"Default","","",,"")} -> -20.167635 | E7: {=[1]!YBPRICE($A7,"0o",E$4,"Price","Swap",E$4,"Default","","",,"")} -> -18.830292 | F7: {=[1]!YBPRICE($A7,"0o",F$4,"Price","Swap",F$4,"Default","","",,"")} -> -19.953387 | G7: {=[1]!YBPRICE($A7,"0o",G$4,"Price","Swap",G$4,"Default","","",,"")} -> -18.640388 | H7: {=[1]!YBPRICE($A7,"0o",H$4,"Price","Swap",H$4,"Default","","",,"")} -> -19.267472 | I7: {=[1]!YBPRICE($A7,"0o",I$4,"Price","Swap",I$4,"Default","","",,"")} -> -18.025948 | ... L7: {=[1]!YBPRICE($A7,"0o",L$4,"Price","Swap",L$4,"Default","","",,"")} -> -17.076102
A8: =[2]Userbonds!A6 -> YBP_SWAP4 | B8: {=[1]!YBPRICE($A8,"0o",B$4,"Price","Swap",B$4,"Default","","",,"")} -> 0.59368199 | C8: {=[1]!YBPRICE($A8,"0o",C$4,"Price","Swap",C$4,"Default","","",,"")} -> 3.7266345 | D8: {=[1]!YBPRICE($A8,"0o",D$4,"Price","Swap",D$4,"Default","","",,"")} -> 3.4296255 | E8: {=[1]!YBPRICE($A8,"0o",E$4,"Price","Swap",E$4,"Default","","",,"")} -> 4.2418458 | F8: {=[1]!YBPRICE($A8,"0o",F$4,"Price","Swap",F$4,"Default","","",,"")} -> 1.8318503 | G8: {=[1]!YBPRICE($A8,"0o",G$4,"Price","Swap",G$4,"Default","","",,"")} -> 3.6708757 | H8: {=[1]!YBPRICE($A8,"0o",H$4,"Price","Swap",H$4,"Default","","",,"")} -> 2.2908352 | I8: {=[1]!YBPRICE($A8,"0o",I$4,"Price","Swap",I$4,"Default","","",,"")} -> 3.0163505 | ... L8: {=[1]!YBPRICE($A8,"0o",L$4,"Price","Swap",L$4,"Default","","",,"")} -> 4.0161128
A9: =[2]Userbonds!A7 -> YBP_SWAP5 | B9: {=[1]!YBPRICE($A9,"0o",B$4,"Price","Swap",B$4,"Default","","",,"")} -> 10.219413 | C9: {=[1]!YBPRICE($A9,"0o",C$4,"Price","Swap",C$4,"Default","","",,"")} -> 8.5929495 | D9: {=[1]!YBPRICE($A9,"0o",D$4,"Price","Swap",D$4,"Default","","",,"")} -> 8.2260622 | E9: {=[1]!YBPRICE($A9,"0o",E$4,"Price","Swap",E$4,"Default","","",,"")} -> 6.8084566 | F9: {=[1]!YBPRICE($A9,"0o",F$4,"Price","Swap",F$4,"Default","","",,"")} -> 7.7435773 | G9: {=[1]!YBPRICE($A9,"0o",G$4,"Price","Swap",G$4,"Default","","",,"")} -> 6.7885067 | H9: {=[1]!YBPRICE($A9,"0o",H$4,"Price","Swap",H$4,"Default","","",,"")} -> 7.3621073 | I9: {=[1]!YBPRICE($A9,"0o",I$4,"Price","Swap",I$4,"Default","","",,"")} -> 6.1627926 | ... L9: {=[1]!YBPRICE($A9,"0o",L$4,"Price","Swap",L$4,"Default","","",,"")} -> 5.6971524
A10: =[2]Userbonds!A8 -> YBP_SWAP6 | B10: {=[1]!YBPRICE($A10,"0o",B$4,"Price","Swap",B$4,"Default","","",,"")} -> 17.50669 | C10: {=[1]!YBPRICE($A10,"0o",C$4,"Price","Swap",C$4,"Default","","",,"")} -> 15.095381 | D10: {=[1]!YBPRICE($A10,"0o",D$4,"Price","Swap",D$4,"Default","","",,"")} -> 14.971789 | E10: {=[1]!YBPRICE($A10,"0o",E$4,"Price","Swap",E$4,"Default","","",,"")} -> 13.836586 | F10: {=[1]!YBPRICE($A10,"0o",F$4,"Price","Swap",F$4,"Default","","",,"")} -> 15.383254 | G10: {=[1]!YBPRICE($A10,"0o",G$4,"Price","Swap",G$4,"Default","","",,"")} -> 13.908617 | H10: {=[1]!YBPRICE($A10,"0o",H$4,"Price","Swap",H$4,"Default","","",,"")} -> 14.81949 | I10: {=[1]!YBPRICE($A10,"0o",I$4,"Price","Swap",I$4,"Default","","",,"")} -> 13.705232 | ... L10: {=[1]!YBPRICE($A10,"0o",L$4,"Price","Swap",L$4,"Default","","",,"")} -> 12.71045
A11: =[2]Userbonds!A9 -> YBP_SWAP7 | B11: {=[1]!YBPRICE($A11,"0o",B$4,"Price","Swap",B$4,"Default","","",,"")} -> -0.1465182 | C11: {=[1]!YBPRICE($A11,"0o",C$4,"Price","Swap",C$4,"Default","","",,"")} -> -0.28274383 | D11: {=[1]!YBPRICE($A11,"0o",D$4,"Price","Swap",D$4,"Default","","",,"")} -> -0.28213437 | E11: {=[1]!YBPRICE($A11,"0o",E$4,"Price","Swap",E$4,"Default","","",,"")} -> -0.42465713 | F11: {=[1]!YBPRICE($A11,"0o",F$4,"Price","Swap",F$4,"Default","","",,"")} -> -0.12772725 | G11: {=[1]!YBPRICE($A11,"0o",G$4,"Price","Swap",G$4,"Default","","",,"")} -> -0.18633636 | H11: {=[1]!YBPRICE($A11,"0o",H$4,"Price","Swap",H$4,"Default","","",,"")} -> -0.0354388 | I11: {=[1]!YBPRICE($A11,"0o",I$4,"Price","Swap",I$4,"Default","","",,"")} -> -0.17672617 | ... L11: {=[1]!YBPRICE($A11,"0o",L$4,"Price","Swap",L$4,"Default","","",,"")} -> -0.18806311
A12: =[2]Userbonds!A10 -> YBP_SWAP8 | B12: {=[1]!YBPRICE($A12,"0o",B$4,"Price","Swap",B$4,"Default","","",,"")} -> 5.6151162 | C12: {=[1]!YBPRICE($A12,"0o",C$4,"Price","Swap",C$4,"Default","","",,"")} -> 4.1522766 | D12: {=[1]!YBPRICE($A12,"0o",D$4,"Price","Swap",D$4,"Default","","",,"")} -> 3.8283746 | E12: {=[1]!YBPRICE($A12,"0o",E$4,"Price","Swap",E$4,"Default","","",,"")} -> 2.4716709 | F12: {=[1]!YBPRICE($A12,"0o",F$4,"Price","Swap",F$4,"Default","","",,"")} -> 3.4397025 | G12: {=[1]!YBPRICE($A12,"0o",G$4,"Price","Swap",G$4,"Default","","",,"")} -> 2.5967652 | H12: {=[1]!YBPRICE($A12,"0o",H$4,"Price","Swap",H$4,"Default","","",,"")} -> 3.2059631 | I12: {=[1]!YBPRICE($A12,"0o",I$4,"Price","Swap",I$4,"Default","","",,"")} -> 2.1184646 | ... L12: {=[1]!YBPRICE($A12,"0o",L$4,"Price","Swap",L$4,"Default","","",,"")} -> 1.8605027
A13: =[2]Userbonds!A11 -> YBP_SWAP9 | B13: {=[1]!YBPRICE($A13,"0o",B$4,"Price","Swap",B$4,"Default","","",,"")} -> -7.8129759 | C13: {=[1]!YBPRICE($A13,"0o",C$4,"Price","Swap",C$4,"Default","","",,"")} -> -5.4313917 | D13: {=[1]!YBPRICE($A13,"0o",D$4,"Price","Swap",D$4,"Default","","",,"")} -> -5.3166153 | E13: {=[1]!YBPRICE($A13,"0o",E$4,"Price","Swap",E$4,"Default","","",,"")} -> -4.0731182 | F13: {=[1]!YBPRICE($A13,"0o",F$4,"Price","Swap",F$4,"Default","","",,"")} -> -5.6770263 | G13: {=[1]!YBPRICE($A13,"0o",G$4,"Price","Swap",G$4,"Default","","",,"")} -> -4.2477116 | H13: {=[1]!YBPRICE($A13,"0o",H$4,"Price","Swap",H$4,"Default","","",,"")} -> -5.2216851 | I13: {=[1]!YBPRICE($A13,"0o",I$4,"Price","Swap",I$4,"Default","","",,"")} -> -4.0551867 | ... L13: {=[1]!YBPRICE($A13,"0o",L$4,"Price","Swap",L$4,"Default","","",,"")} -> -3.2977582
A14: =[2]Userbonds!A12 -> YBP_SWAP10 | B14: {=[1]!YBPRICE($A14,"0o",B$4,"Price","Swap",B$4,"Default","","",,"")} -> -6.4700124 | C14: {=[1]!YBPRICE($A14,"0o",C$4,"Price","Swap",C$4,"Default","","",,"")} -> -5.0634304 | D14: {=[1]!YBPRICE($A14,"0o",D$4,"Price","Swap",D$4,"Default","","",,"")} -> -4.7142323 | E14: {=[1]!YBPRICE($A14,"0o",E$4,"Price","Swap",E$4,"Default","","",,"")} -> -3.3725627 | F14: {=[1]!YBPRICE($A14,"0o",F$4,"Price","Swap",F$4,"Default","","",,"")} -> -4.2920906 | G14: {=[1]!YBPRICE($A14,"0o",G$4,"Price","Swap",G$4,"Default","","",,"")} -> -3.4644829 | H14: {=[1]!YBPRICE($A14,"0o",H$4,"Price","Swap",H$4,"Default","","",,"")} -> -4.0466424 | I14: {=[1]!YBPRICE($A14,"0o",I$4,"Price","Swap",I$4,"Default","","",,"")} -> -2.9857793 | ... L14: {=[1]!YBPRICE($A14,"0o",L$4,"Price","Swap",L$4,"Default","","",,"")} -> -2.6833743
A15: =[2]Userbonds!A13 -> YBP_SWAP11 | B15: {=[1]!YBPRICE($A15,"0o",B$4,"Price","Swap",B$4,"Default","","",,"")} -> -4.3786812 | C15: {=[1]!YBPRICE($A15,"0o",C$4,"Price","Swap",C$4,"Default","","",,"")} -> -3.804607 | D15: {=[1]!YBPRICE($A15,"0o",D$4,"Price","Swap",D$4,"Default","","",,"")} -> -3.5046026 | E15: {=[1]!YBPRICE($A15,"0o",E$4,"Price","Swap",E$4,"Default","","",,"")} -> -2.816385 | F15: {=[1]!YBPRICE($A15,"0o",F$4,"Price","Swap",F$4,"Default","","",,"")} -> -3.2292645 | G15: {=[1]!YBPRICE($A15,"0o",G$4,"Price","Swap",G$4,"Default","","",,"")} -> -2.8011788 | H15: {=[1]!YBPRICE($A15,"0o",H$4,"Price","Swap",H$4,"Default","","",,"")} -> -3.0345101 | I15: {=[1]!YBPRICE($A15,"0o",I$4,"Price","Swap",I$4,"Default","","",,"")} -> -2.4746417 | ... L15: {=[1]!YBPRICE($A15,"0o",L$4,"Price","Swap",L$4,"Default","","",,"")} -> -1.9213708
A16: =[2]Userbonds!A14 -> YBP_SWAP12 | B16: {=[1]!YBPRICE($A16,"0o",B$4,"Price","Swap",B$4,"Default","","",,"")} -> -8.6655971 | C16: {=[1]!YBPRICE($A16,"0o",C$4,"Price","Swap",C$4,"Default","","",,"")} -> -6.1631587 | D16: {=[1]!YBPRICE($A16,"0o",D$4,"Price","Swap",D$4,"Default","","",,"")} -> -6.0874951 | E16: {=[1]!YBPRICE($A16,"0o",E$4,"Price","Swap",E$4,"Default","","",,"")} -> -4.9016975 | F16: {=[1]!YBPRICE($A16,"0o",F$4,"Price","Swap",F$4,"Default","","",,"")} -> -6.6115041 | G16: {=[1]!YBPRICE($A16,"0o",G$4,"Price","Swap",G$4,"Default","","",,"")} -> -5.1183498 | H16: {=[1]!YBPRICE($A16,"0o",H$4,"Price","Swap",H$4,"Default","","",,"")} -> -6.1438449 | I16: {=[1]!YBPRICE($A16,"0o",I$4,"Price","Swap",I$4,"Default","","",,"")} -> -5.000821 | ... L16: {=[1]!YBPRICE($A16,"0o",L$4,"Price","Swap",L$4,"Default","","",,"")} -> -4.1597888
... A34: =[2]Userbonds!A32 -> YBP_SWAP30 | B34: {=[1]!YBPRICE($A34,"0o",B$4,"Price","Swap",B$4,"Default","","",,"")} -> 0.0286024 | C34: {=[1]!YBPRICE($A34,"0o",C$4,"Price","Swap",C$4,"Default","","",,"")} -> 2.6023864 | D34: {=[1]!YBPRICE($A34,"0o",D$4,"Price","Swap",D$4,"Default","","",,"")} -> 2.6362853 | E34: {=[1]!YBPRICE($A34,"0o",E$4,"Price","Swap",E$4,"Default","","",,"")} -> 3.8439739 | F34: {=[1]!YBPRICE($A34,"0o",F$4,"Price","Swap",F$4,"Default","","",,"")} -> 1.9983939 | G34: {=[1]!YBPRICE($A34,"0o",G$4,"Price","Swap",G$4,"Default","","",,"")} -> 3.497458 | H34: {=[1]!YBPRICE($A34,"0o",H$4,"Price","Swap",H$4,"Default","","",,"")} -> 2.3597367 | I34: {=[1]!YBPRICE($A34,"0o",I$4,"Price","Swap",I$4,"Default","","",,"")} -> 3.4212143 | ... L34: {=[1]!YBPRICE($A34,"0o",L$4,"Price","Swap",L$4,"Default","","",,"")} -> 4.0059398
B35: =SUM(B5:B34) -> -29.45144 | C35: =SUM(C5:C34) -> -23.774932 | D35: =SUM(D5:D34) -> -25.416255 | E35: =SUM(E5:E34) -> -26.939819 | F35: =SUM(F5:F34) -> -31.554744 | G35: =SUM(G5:G34) -> -27.963381 | H35: =SUM(H5:H34) -> -30.455344 | I35: =SUM(I5:I34) -> -31.478625 | ... L35: =SUM(L5:L34) -> -27.938076
A38: Swap Prices based on notional amount (MTM)
A39: Dates | B39: 45688 | C39: 45716 | D39: 45747 | E39: 45777 | F39: 45807 | G39: 45838 | H39: 45869 | I39: 45898 | J39: 45930 | K39: 45961 | L39: 45989
A40: Swap 1 | B40: =(B5/100)*Portfolio!$B3 -> -71695.616 | C40: =(C5/100)*Portfolio!$B3 -> -57909.392 | D40: =(D5/100)*Portfolio!$B3 -> -51960.673 | E40: =(E5/100)*Portfolio!$B3 -> -38163.054 | F40: =(F5/100)*Portfolio!$B3 -> -51351.163 | G40: =(G5/100)*Portfolio!$B3 -> -40673.84 | H40: =(H5/100)*Portfolio!$B3 -> -41324.97 | I40: =(I5/100)*Portfolio!$B3 -> -27401.638 | ... L40: =(L5/100)*Portfolio!$B3 -> -6137.0768
A41: Swap 2 | B41: =(B6/100)*Portfolio!$B4 -> -120623.86 | C41: =(C6/100)*Portfolio!$B$4 -> 4010.5042 | D41: =(D6/100)*Portfolio!$B$4 -> 9309.0735 | E41: =(E6/100)*Portfolio!$B$4 -> 79079.716 | F41: =(F6/100)*Portfolio!$B$4 -> -7483.1268 | G41: =(G6/100)*Portfolio!$B$4 -> 65974.135 | H41: =(H6/100)*Portfolio!$B$4 -> 12069.542 | I41: =(I6/100)*Portfolio!$B$4 -> 77680.56 | J41: =(J6/100)*Portfolio!$B$4 -> 85123.321 | ... L41: =(L6/100)*Portfolio!$B$4 -> 108428.91
A42: Swap 3 | B42: =(B7/100)*Portfolio!$B5 -> -1140771.5 | C42: =(C7/100)*Portfolio!$B5 -> -1035536.2 | D42: =(D7/100)*Portfolio!$B5 -> -1019675.6 | E42: =(E7/100)*Portfolio!$B5 -> -952059.59 | F42: =(F7/100)*Portfolio!$B5 -> -1008843.3 | G42: =(G7/100)*Portfolio!$B5 -> -942458.04 | H42: =(H7/100)*Portfolio!$B5 -> -974163.39 | I42: =(I7/100)*Portfolio!$B5 -> -911391.92 | ... L42: =(L7/100)*Portfolio!$B5 -> -863367.7
A43: Swap 4 | B43: =(B8/100)*Portfolio!$B6 -> 57504.038 | C43: =(C8/100)*Portfolio!$B6 -> 360961.82 | D43: =(D8/100)*Portfolio!$B6 -> 332193.52 | E43: =(E8/100)*Portfolio!$B6 -> 410865.19 | F43: =(F8/100)*Portfolio!$B6 -> 177433.02 | G43: =(G8/100)*Portfolio!$B6 -> 355561.02 | H43: =(H8/100)*Portfolio!$B6 -> 221890.3 | I43: =(I8/100)*Portfolio!$B6 -> 292163.71 | ... L43: =(L8/100)*Portfolio!$B6 -> 389000.69
A44: Swap 5 | B44: =(B9/100)*Portfolio!$B7 -> 697168.36 | C44: =(C9/100)*Portfolio!$B7 -> 586211.01 | D44: =(D9/100)*Portfolio!$B7 -> 561181.96 | E44: =(E9/100)*Portfolio!$B7 -> 464472.91 | F44: =(F9/100)*Portfolio!$B7 -> 528266.84 | G44: =(G9/100)*Portfolio!$B7 -> 463111.93 | H44: =(H9/100)*Portfolio!$B7 -> 502242.96 | I44: =(I9/100)*Portfolio!$B7 -> 420425.71 | ... L44: =(L9/100)*Portfolio!$B7 -> 388659.74
A45: Swap 6 | B45: =(B10/100)*Portfolio!$B8 -> 652474.35 | C45: =(C10/100)*Portfolio!$B8 -> 562604.86 | D45: =(D10/100)*Portfolio!$B8 -> 557998.57 | E45: =(E10/100)*Portfolio!$B8 -> 515689.56 | F45: =(F10/100)*Portfolio!$B8 -> 573333.86 | G45: =(G10/100)*Portfolio!$B8 -> 518374.14 | H45: =(H10/100)*Portfolio!$B8 -> 552322.4 | I45: =(I10/100)*Portfolio!$B8 -> 510793.99 | ... L45: =(L10/100)*Portfolio!$B8 -> 473718.46
A46: Swap 7 | B46: =(B11/100)*Portfolio!$B9 -> -4775.0281 | C46: =(C11/100)*Portfolio!$B9 -> -9214.6214 | D46: =(D11/100)*Portfolio!$B9 -> -9194.7591 | E46: =(E11/100)*Portfolio!$B9 -> -13839.576 | F46: =(F11/100)*Portfolio!$B9 -> -4162.6311 | G46: =(G11/100)*Portfolio!$B9 -> -6072.702 | H46: =(H11/100)*Portfolio!$B9 -> -1154.9505 | I46: =(I11/100)*Portfolio!$B9 -> -5759.5059 | ... L46: =(L11/100)*Portfolio!$B9 -> -6128.9768
A47: Swap 8 | B47: =(B12/100)*Portfolio!$B10 -> 49413.022 | C47: =(C12/100)*Portfolio!$B10 -> 36540.034 | D47: =(D12/100)*Portfolio!$B10 -> 33689.697 | E47: =(E12/100)*Portfolio!$B10 -> 21750.704 | F47: =(F12/100)*Portfolio!$B10 -> 30269.382 | G47: =(G12/100)*Portfolio!$B10 -> 22851.534 | H47: =(H12/100)*Portfolio!$B10 -> 28212.475 | I47: =(I12/100)*Portfolio!$B10 -> 18642.488 | ... L47: =(L12/100)*Portfolio!$B10 -> 16372.424
A48: Swap 9 | B48: =(B13/100)*Portfolio!$B11 -> -631366.59 | C48: =(C13/100)*Portfolio!$B11 -> -438910.77 | D48: =(D13/100)*Portfolio!$B11 -> -429635.68 | E48: =(E13/100)*Portfolio!$B11 -> -329148.68 | F48: =(F13/100)*Portfolio!$B11 -> -458760.5 | G48: =(G13/100)*Portfolio!$B11 -> -343257.57 | H48: =(H13/100)*Portfolio!$B11 -> -421964.38 | I48: =(I13/100)*Portfolio!$B11 -> -327699.64 | ... L48: =(L13/100)*Portfolio!$B11 -> -266491.84
A49: Swap 10 | B49: =(B14/100)*Portfolio!$B12 -> -22968.544 | C49: =(C14/100)*Portfolio!$B12 -> -17975.178 | D49: =(D14/100)*Portfolio!$B12 -> -16735.524 | E49: =(E14/100)*Portfolio!$B12 -> -11972.598 | F49: =(F14/100)*Portfolio!$B12 -> -15236.922 | G49: =(G14/100)*Portfolio!$B12 -> -12298.914 | H49: =(H14/100)*Portfolio!$B12 -> -14365.581 | I49: =(I14/100)*Portfolio!$B12 -> -10599.517 | ... L49: =(L14/100)*Portfolio!$B12 -> -9525.9788
A50: Swap 11 | B50: =(B15/100)*Portfolio!$B13 -> -101191.32 | C50: =(C15/100)*Portfolio!$B13 -> -87924.467 | D50: =(D15/100)*Portfolio!$B13 -> -80991.367 | E50: =(E15/100)*Portfolio!$B13 -> -65086.658 | F50: =(F15/100)*Portfolio!$B13 -> -74628.302 | G50: =(G15/100)*Portfolio!$B13 -> -64735.241 | H50: =(H15/100)*Portfolio!$B13 -> -70127.528 | I50: =(I15/100)*Portfolio!$B13 -> -57188.969 | ... L50: =(L15/100)*Portfolio!$B13 -> -44402.88
A51: Swap 12 | B51: =(B16/100)*Portfolio!$B14 -> -715778.32 | C51: =(C16/100)*Portfolio!$B14 -> -509076.91 | D51: =(D16/100)*Portfolio!$B14 -> -502827.1 | E51: =(E16/100)*Portfolio!$B14 -> -404880.21 | F51: =(F16/100)*Portfolio!$B14 -> -546110.24 | G51: =(G16/100)*Portfolio!$B14 -> -422775.69 | H51: =(H16/100)*Portfolio!$B14 -> -507481.59 | I51: =(I16/100)*Portfolio!$B14 -> -413067.81 | ... L51: =(L16/100)*Portfolio!$B14 -> -343598.56
A52: Swap 13 | B52: =(B17/100)*Portfolio!$B15 -> -10090.204 | C52: =(C17/100)*Portfolio!$B15 -> 44552.934 | D52: =(D17/100)*Portfolio!$B15 -> 46714.07 | E52: =(E17/100)*Portfolio!$B15 -> 76518.481 | F52: =(F17/100)*Portfolio!$B15 -> 37800.131 | G52: =(G17/100)*Portfolio!$B15 -> 70011.09 | H52: =(H17/100)*Portfolio!$B15 -> 45776.663 | I52: =(I17/100)*Portfolio!$B15 -> 73971.545 | ... L52: =(L17/100)*Portfolio!$B15 -> 86814.034
A53: Swap 14 | B53: =(B18/100)*Portfolio!$B16 -> -113871.46 | C53: =(C18/100)*Portfolio!$B16 -> -78268.88 | D53: =(D18/100)*Portfolio!$B16 -> -76223.688 | E53: =(E18/100)*Portfolio!$B16 -> -57198.997 | F53: =(F18/100)*Portfolio!$B16 -> -81034.659 | G53: =(G18/100)*Portfolio!$B16 -> -59599.703 | H53: =(H18/100)*Portfolio!$B16 -> -74310.361 | I53: =(I18/100)*Portfolio!$B16 -> -55991.714 | ... L53: =(L18/100)*Portfolio!$B16 -> -45017.586
... A69: Swap 30 | B69: =(B34/100)*Portfolio!$B32 -> 2238.4238 | C69: =(C34/100)*Portfolio!$B32 -> 203662.76 | D69: =(D34/100)*Portfolio!$B32 -> 206315.68 | E69: =(E34/100)*Portfolio!$B32 -> 300829.4 | F69: =(F34/100)*Portfolio!$B32 -> 156394.31 | G69: =(G34/100)*Portfolio!$B32 -> 273711.06 | H69: =(H34/100)*Portfolio!$B32 -> 184673 | I69: =(I34/100)*Portfolio!$B32 -> 267744.23 | ... L69: =(L34/100)*Portfolio!$B32 -> 313504.85
A70: Portfolio Values | B70: =SUM(B40:B69) -> -2089856.9 | C70: =SUM(C40:C69) -> -1687202.2 | D70: =SUM(D40:D69) -> -1783305.1 | E70: =SUM(E40:E69) -> -1840437.4 | F70: =SUM(F40:F69) -> -2177936.4 | G70: =SUM(G40:G69) -> -1927525.8 | H70: =SUM(H40:H69) -> -2101351 | I70: =SUM(I40:I69) -> -2143127.8 | ... L70: =SUM(L40:L69) -> -1899908.1

Sheet Part 2 - Hedges
A1: Insert 11 hedges here using the solver
A2: Hint: you can go between sheets and solve for fixed rates using the prices from the part 1 sheet
A3: Dates | B3: 45688 | C3: 45716 | D3: 45747 | E3: 45777 | F3: 45807 | G3: 45838 | H3: 45869 | I3: 45898 | J3: 45930 | K3: 45961 | L3: 45989
A4: Portfolio Price MTM | B4: ='Part 1 - Portfolio'!B70 -> -2089856.9 | C4: ='Part 1 - Portfolio'!C70 -> -1687202.2 | D4: ='Part 1 - Portfolio'!D70 -> -1783305.1 | E4: ='Part 1 - Portfolio'!E70 -> -1840437.4 | F4: ='Part 1 - Portfolio'!F70 -> -2177936.4 | G4: ='Part 1 - Portfolio'!G70 -> -1927525.8 | H4: ='Part 1 - Portfolio'!H70 -> -2101351 | I4: ='Part 1 - Portfolio'!I70 -> -2143127.8 | ... L4: ='Part 1 - Portfolio'!L70 -> -1899908.1
A5: Hedge Price MTM | B5: =-B4 -> 2089856.9 | C5: =-C4 -> 1687202.2 | D5: =-D4 -> 1783305.1 | E5: =-E4 -> 1840437.4 | F5: =-F4 -> 2177936.4 | G5: =-G4 -> 1927525.8 | H5: =-H4 -> 2101351 | I5: =-I4 -> 2143127.8 | ... L5: =-L4 -> 1899908.1
A8: Pricing Date | B8: Solver | C8: Userbond | D8: Price | E8: CUSIP | F8: SECTYPE | G8: COUP | H8: PAYFREQ | I8: MATDATE | J8: DTDATE | K8: FCPDATE
A9: 45688 | B9: {=[1]!YBSOLVER(D9,B5,G9,0.01,"5%","")} -> -97.532708 | C9: {=[1]!YBPORT(E9,$E$8:$K$8,E9:K9)} -> YBP_BOND1_5 | D9: {=[1]!YBPRICE(C9,"0o",A9,"Price","Swap",A9,"Default","","",,"")/100*1000000000} -> 2089856.9 | E9: BOND1 | F9: BOND | G9: -97.532708 | H9: 12 | I9: 46053 | J9: 45688 | K9: =J9+31 -> 45719
A10: 45716 | B10: {=[1]!YBSOLVER(D10,C5,G10,0.01,"5%","")} -> -97.978016 | C10: {=[1]!YBPORT(E10,$E$8:$K$8,E10:K10)} -> YBP_BOND2_6 | D10: {=[1]!YBPRICE(C10,"0o",A10,"Price","Swap",A10,"Default","","",,"")/100*1000000000} -> 1687202.2 | E10: BOND2 | F10: BOND | G10: -97.978016 | H10: 12 | I10: 46081 | J10: 45716 | K10: =J10+31 -> 45747
A11: 45747 | B11: {=[1]!YBSOLVER(D11,D5,G11,0.01,"5%","")} -> -97.964138 | C11: {=[1]!YBPORT(E11,$E$8:$K$8,E11:K11)} -> YBP_BOND3_5 | D11: {=[1]!YBPRICE(C11,"0o",A11,"Price","Swap",A11,"Default","","",,"")/100*1000000000} -> 1783305.1 | E11: BOND3 | F11: BOND | G11: -97.964138 | H11: 12 | I11: 46112 | J11: 45747 | K11: =J11+30 -> 45777
A12: 45777 | B12: {=[1]!YBSOLVER(D12,E5,G12,0.01,"5%","")} -> -98.120626 | C12: {=[1]!YBPORT(E12,$E$8:$K$8,E12:K12)} -> YBP_BOND4_5 | D12: {=[1]!YBPRICE(C12,"0o",A12,"Price","Swap",A12,"Default","","",,"")/100*1000000000} -> 1840437.4 | E12: BOND4 | F12: BOND | G12: -98.120626 | H12: 12 | I12: 46142 | J12: 45777 | K12: =J12+30 -> 45807
A13: 45807 | B13: {=[1]!YBSOLVER(D13,F5,G13,0.01,"5%","")} -> -97.90679 | C13: {=[1]!YBPORT(E13,$E$8:$K$8,E13:K13)} -> YBP_BOND5_5 | D13: {=[1]!YBPRICE(C13,"0o",A13,"Price","Swap",A13,"Default","","",,"")/100*1000000000} -> 2177936.3 | E13: BOND5 | F13: BOND | G13: -97.90679 | H13: 12 | I13: 46172 | J13: 45807 | K13: =J13+31 -> 45838
A14: 45838 | B14: {=[1]!YBSOLVER(D14,G5,G14,0.01,"5%","")} -> -98.038067 | C14: {=[1]!YBPORT(E14,$E$8:$K$8,E14:K14)} -> YBP_BOND6_5 | D14: {=[1]!YBPRICE(C14,"0o",A14,"Price","Swap",A14,"Default","","",,"")/100*1000000000} -> 1927525.8 | E14: BOND6 | F14: BOND | G14: -98.038067 | H14: 12 | I14: 46203 | J14: 45838 | K14: =J14+31 -> 45869
A15: 45869 | B15: {=[1]!YBSOLVER(D15,H5,G15,0.01,"5%","")} -> -97.623085 | C15: {=[1]!YBPORT(E15,$E$8:$K$8,E15:K15)} -> YBP_BOND7_5 | D15: {=[1]!YBPRICE(C15,"0o",A15,"Price","Swap",A15,"Default","","",,"")/100*1000000000} -> 2101351 | E15: BOND7 | F15: BOND | G15: -97.623085 | H15: 12 | I15: 46234 | J15: 45869 | K15: =J15+29 -> 45898
A16: 45898 | B16: {=[1]!YBSOLVER(D16,I5,G16,0.01,"5%","")} -> -97.768063 | C16: {=[1]!YBPORT(E16,$E$8:$K$8,E16:K16)} -> YBP_BOND8_5 | D16: {=[1]!YBPRICE(C16,"0o",A16,"Price","Swap",A16,"Default","","",,"")/100*1000000000} -> 2143127.8 | E16: BOND8 | F16: BOND | G16: -97.768063 | H16: 12 | I16: 46263 | J16: 45898 | K16: =J16+32 -> 45930
A17: 45930 | B17: {=[1]!YBSOLVER(D17,J5,G17,0.01,"5%","")} -> -98.104298 | C17: {=[1]!YBPORT(E17,$E$8:$K$8,E17:K17)} -> YBP_BOND9_5 | D17: {=[1]!YBPRICE(C17,"0o",A17,"Price","Swap",A17,"Default","","",,"")/100*1000000000} -> 1906881.3 | E17: BOND9 | F17: BOND | G17: -98.104298 | H17: 12 | I17: 46295 | J17: 45930 | K17: =J17+31 -> 45961
A18: 45961 | B18: {=[1]!YBSOLVER(D18,K5,G18,0.01,"5%","")} -> -98.09921 | C18: {=[1]!YBPORT(E18,$E$8:$K$8,E18:K18)} -> YBP_BOND10_5 | D18: {=[1]!YBPRICE(C18,"0o",A18,"Price","Swap",A18,"Default","","",,"")/100*1000000000} -> 1912780.8 | E18: BOND10 | F18: BOND | G18: -98.09921 | H18: 12 | I18: 46326 | J18: 45961 | K18: =J18+30 -> 45991
A19: 45989 | B19: {=[1]!YBSOLVER(D19,L5,G19,0.01,"5%","")} -> -98.153389 | C19: {=[1]!YBPORT(E19,$E$8:$K$8,E19:K19)} -> YBP_BOND11_5 | D19: {=[1]!YBPRICE(C19,"0o",A19,"Price","Swap",A19,"Default","","",,"")/100*1000000000} -> 1899908 | E19: BOND11 | F19: BOND | G19: -98.153389 | H19: 12 | I19: 46354 | J19: 45989 | K19: =J19+30 -> 46019

Sheet Part 3 - Shocks
A1: Insert 11 shocked curves, 1 for each month end of the year so far
A3: Dates | B3: 45688 | C3: 45716 | D3: 45747 | E3: 45777 | F3: 45807 | G3: 45838 | H3: 45869 | I3: 45898 | J3: 45930 | K3: 45961 | L3: 45989
A4: Tenors | B4: =1/12 -> 0.083333333 | C4: =2/12 -> 0.16666667 | D4: =3/12 -> 0.25 | E4: =4/12 -> 0.33333333 | F4: =5/12 -> 0.41666667 | G4: =6/12 -> 0.5 | H4: =7/12 -> 0.58333333 | I4: =8/12 -> 0.66666667 | J4: =9/12 -> 0.75 | K4: =10/12 -> 0.83333333 | L4: =11/12 -> 0.91666667
A5: Spot Curve | B5: {=[1]!YBCURVEANALY("USD","Swap","SpotRate",B3,B4,"","","Spot",0,"","Y")} -> 4.5661 | C5: {=[1]!YBCURVEANALY("USD","Swap","SpotRate",C3,C4,"","","Spot",0,"","Y")} -> 4.5616 | D5: {=[1]!YBCURVEANALY("USD","Swap","SpotRate",D3,D4,"","","Spot",0,"","Y")} -> 4.546 | E5: {=[1]!YBCURVEANALY("USD","Swap","SpotRate",E3,E4,"","","Spot",0,"","Y")} -> 4.4562667 | F5: {=[1]!YBCURVEANALY("USD","Swap","SpotRate",F3,F4,"","","Spot",0,"","Y")} -> 4.5330333 | G5: {=[1]!YBCURVEANALY("USD","Swap","SpotRate",G3,G4,"","","Spot",0,"","Y")} -> 4.3987 | H5: {=[1]!YBCURVEANALY("USD","Swap","SpotRate",H3,H4,"","","Spot",0,"","Y")} -> 4.4892667 | I5: {=[1]!YBCURVEANALY("USD","Swap","SpotRate",I3,I4,"","","Spot",0,"","Y")} -> 4.1978667 | ... L5: {=[1]!YBCURVEANALY("USD","Swap","SpotRate",L3,L4,"","","Spot",0,"","Y")} -> 3.8288333
A6: Shocked Curve (50bps) | B6: {=[1]!YBCURVEANALY("USD","Swap","SpotRate",B3,B4,"","","Spot",50,"","Y")} -> 5.0661 | C6: {=[1]!YBCURVEANALY("USD","Swap","SpotRate",C3,C4,"","","Spot",50,"","Y")} -> 5.0616 | D6: {=[1]!YBCURVEANALY("USD","Swap","SpotRate",D3,D4,"","","Spot",50,"","Y")} -> 5.046 | E6: {=[1]!YBCURVEANALY("USD","Swap","SpotRate",E3,E4,"","","Spot",50,"","Y")} -> 4.9562667 | F6: {=[1]!YBCURVEANALY("USD","Swap","SpotRate",F3,F4,"","","Spot",50,"","Y")} -> 5.0330333 | G6: {=[1]!YBCURVEANALY("USD","Swap","SpotRate",G3,G4,"","","Spot",50,"","Y")} -> 4.8987 | H6: {=[1]!YBCURVEANALY("USD","Swap","SpotRate",H3,H4,"","","Spot",50,"","Y")} -> 4.9892667 | I6: {=[1]!YBCURVEANALY("USD","Swap","SpotRate",I3,I4,"","","Spot",50,"","Y")} -> 4.6978667 | ... L6: {=[1]!YBCURVEANALY("USD","Swap","SpotRate",L3,L4,"","","Spot",50,"","Y")} -> 4.3288333
A7: User Curve Id | B7: {=[1]!YBSW("50bpslessyears","USD",B4:L4,B6:L6,"Absolute","Spot")} -> YBSW_50BPSLESSYEARS_1
A9: Shocked Swap prices MTM
A10: Dates | B10: 45688 | C10: 45716 | D10: 45747 | E10: 45777 | F10: 45807 | G10: 45838 | H10: 45869 | I10: 45898 | J10: 45930 | K10: 45961 | L10: 45989
A11: ='Part 1 - Portfolio'!A5 -> YBP_SWAP1 | B11: {=[1]!YBPRICE($A11,"0o",B$10,"Price","Swap",B$10,"Default","","",,"",,$B$7)/100*Portfolio!$B3} -> -61730.706 | C11: {=[1]!YBPRICE($A11,"0o",C$10,"Price","Swap",C$10,"Default","","",,"",,$B$7)/100*Portfolio!$B3} -> -59625.15 | D11: {=[1]!YBPRICE($A11,"0o",D$10,"Price","Swap",D$10,"Default","","",,"",,$B$7)/100*Portfolio!$B3} -> -60407.277 | E11: {=[1]!YBPRICE($A11,"0o",E$10,"Price","Swap",E$10,"Default","","",,"",,$B$7)/100*Portfolio!$B3} -> -61496.989 | F11: {=[1]!YBPRICE($A11,"0o",F$10,"Price","Swap",F$10,"Default","","",,"",,$B$7)/100*Portfolio!$B3} -> -64187.624 | G11: {=[1]!YBPRICE($A11,"0o",G$10,"Price","Swap",G$10,"Default","","",,"",,$B$7)/100*Portfolio!$B3} -> -63759.59 | H11: {=[1]!YBPRICE($A11,"0o",H$10,"Price","Swap",H$10,"Default","","",,"",,$B$7)/100*Portfolio!$B3} -> -59688.021 | I11: {=[1]!YBPRICE($A11,"0o",I$10,"Price","Swap",I$10,"Default","","",,"",,$B$7)/100*Portfolio!$B3} -> -51589.72 | ... L11: {=[1]!YBPRICE($A11,"0o",L$10,"Price","Swap",L$10,"Default","","",,"",,$B$7)/100*Portfolio!$B3} -> -20507.308
A12: ='Part 1 - Portfolio'!A6 -> YBP_SWAP2 | B12: {=[1]!YBPRICE($A12,"0o",B$10,"Price","Swap",B$10,"Default","","",,"",,$B$7)/100*Portfolio!$B4} -> -55367.498 | C12: {=[1]!YBPRICE($A12,"0o",C$10,"Price","Swap",C$10,"Default","","",,"",,$B$7)/100*Portfolio!$B4} -> 25481.324 | D12: {=[1]!YBPRICE($A12,"0o",D$10,"Price","Swap",D$10,"Default","","",,"",,$B$7)/100*Portfolio!$B4} -> 7516.6886 | E12: {=[1]!YBPRICE($A12,"0o",E$10,"Price","Swap",E$10,"Default","","",,"",,$B$7)/100*Portfolio!$B4} -> -4467.9238 | F12: {=[1]!YBPRICE($A12,"0o",F$10,"Price","Swap",F$10,"Default","","",,"",,$B$7)/100*Portfolio!$B4} -> 14957.16 | G12: {=[1]!YBPRICE($A12,"0o",G$10,"Price","Swap",G$10,"Default","","",,"",,$B$7)/100*Portfolio!$B4} -> 24165.201 | H12: {=[1]!YBPRICE($A12,"0o",H$10,"Price","Swap",H$10,"Default","","",,"",,$B$7)/100*Portfolio!$B4} -> 46376.011 | I12: {=[1]!YBPRICE($A12,"0o",I$10,"Price","Swap",I$10,"Default","","",,"",,$B$7)/100*Portfolio!$B4} -> -3888.8818 | ... L12: {=[1]!YBPRICE($A12,"0o",L$10,"Price","Swap",L$10,"Default","","",,"",,$B$7)/100*Portfolio!$B4} -> -63519.139
